<?xml version="1.0" encoding="UTF-8"?>
<robot name="Robot">
    <link name="base">
        <inertial>
            <mass value="0"/>
            <inertia ixx="0" ixy="0" ixz="0" iyy="0" iyz="0" izz="0"/>
        </inertial>
    </link>
    <link name="base_link">
        <inertial>
            <origin rpy="0.00000000 0.00000000 0.00000000" xyz="0.00000000 0.00000000 0.00000000"/>
            <mass value="1.00000000"/>
            <inertia ixx="1.00000000" ixy="0.00000000" ixz="0.00000000" iyy="1.00000000" iyz="0.00000000" izz="1.00000000"/>
        </inertial>
        <visual>
            <origin rpy="0.00000000 0.00000000 0.00000000" xyz="0.00000000 0.00000000 0.00000000"/>
            <geometry>
                <mesh filename="meshes/visual/base_link.stl" scale="1.00000000 1.00000000 1.00000000"/>
            </geometry>
            <material name="">
                <color rgba="0.3450980 0.3647059 0.3686275 1"/>
            </material>
        </visual>
    </link>
    <link name="link_1">
        <inertial>
            <origin rpy="0.00000000 0.00000000 0.00000000" xyz="0.00000000 0.00000000 0.00000000"/>
            <mass value="1.00000000"/>
            <inertia ixx="1.00000000" ixy="0.00000000" ixz="0.00000000" iyy="1.00000000" iyz="0.00000000" izz="1.00000000"/>
        </inertial>
        <visual>
            <origin rpy="0.00000000 0.00000000 0.00000000" xyz="0.00000000 0.00000000 0.00000000"/>
            <geometry>
                <mesh filename="meshes/visual/link_1.stl" scale="1.00000000 1.00000000 1.00000000"/>
            </geometry>
            <material name="">
                <color rgba="0.3450980 0.3647059 0.3686275 1"/>
            </material>
        </visual>
    </link>
    <link name="link_2">
        <inertial>
            <origin rpy="0.00000000 0.00000000 0.00000000" xyz="0.00000000 0.00000000 0.00000000"/>
            <mass value="1.00000000"/>
            <inertia ixx="1.00000000" ixy="0.00000000" ixz="0.00000000" iyy="1.00000000" iyz="0.00000000" izz="1.00000000"/>
        </inertial>
        <visual>
            <origin rpy="0.00000000 0.00000000 0.00000000" xyz="0.00000000 0.00000000 0.00000000"/>
            <geometry>
                <mesh filename="meshes/visual/link_2.stl" scale="1.00000000 1.00000000 1.00000000"/>
            </geometry>
            <material name="">
                <color rgba="0.3450980 0.3647059 0.3686275 1"/>
            </material>
        </visual>
    </link>
    <link name="link_3">
        <inertial>
            <origin rpy="0.00000000 0.00000000 0.00000000" xyz="0.00000000 0.00000000 0.00000000"/>
            <mass value="1.00000000"/>
            <inertia ixx="1.00000000" ixy="0.00000000" ixz="0.00000000" iyy="1.00000000" iyz="0.00000000" izz="1.00000000"/>
        </inertial>
        <visual>
            <origin rpy="0.00000000 0.00000000 0.00000000" xyz="0.00000000 0.00000000 0.00000000"/>
            <geometry>
                <mesh filename="meshes/visual/link_3.stl" scale="1.00000000 1.00000000 1.00000000"/>
            </geometry>
            <material name="">
                <color rgba="0.3450980 0.3647059 0.3686275 1"/>
            </material>
        </visual>
    </link>
    <link name="link_4">
        <inertial>
            <origin rpy="0.00000000 0.00000000 0.00000000" xyz="0.00000000 0.00000000 0.00000000"/>
            <mass value="1.00000000"/>
            <inertia ixx="1.00000000" ixy="0.00000000" ixz="0.00000000" iyy="1.00000000" iyz="0.00000000" izz="1.00000000"/>
        </inertial>
        <visual>
            <origin rpy="0.00000000 0.00000000 0.00000000" xyz="0.00000000 0.00000000 0.00000000"/>
            <geometry>
                <mesh filename="meshes/visual/link_4.stl" scale="1.00000000 1.00000000 1.00000000"/>
            </geometry>
            <material name="">
                <color rgba="0.7725490 0.7803922 0.7686275 1"/>
            </material>
        </visual>
    </link>
    <link name="link_5">
        <inertial>
            <origin rpy="0.00000000 0.00000000 0.00000000" xyz="0.00000000 0.00000000 0.00000000"/>
            <mass value="1.00000000"/>
            <inertia ixx="1.00000000" ixy="0.00000000" ixz="0.00000000" iyy="1.00000000" iyz="0.00000000" izz="1.00000000"/>
        </inertial>
        <visual>
            <origin rpy="0.00000000 0.00000000 0.00000000" xyz="0.00000000 0.00000000 0.00000000"/>
            <geometry>
                <mesh filename="meshes/visual/link_5.stl" scale="1.00000000 1.00000000 1.00000000"/>
            </geometry>
            <material name="">
                <color rgba="0.7725490 0.7803922 0.7686275 1"/>
            </material>
        </visual>
    </link>
    <link name="link_6">
        <inertial>
            <origin rpy="0.00000000 0.00000000 0.00000000" xyz="0.00000000 0.00000000 0.00000000"/>
            <mass value="1.00000000"/>
            <inertia ixx="1.00000000" ixy="0.00000000" ixz="0.00000000" iyy="1.00000000" iyz="0.00000000" izz="1.00000000"/>
        </inertial>
        <visual>
            <origin rpy="0.00000000 0.00000000 0.00000000" xyz="0.00000000 0.00000000 0.00000000"/>
            <geometry>
                <mesh filename="meshes/visual/link_6.stl" scale="1.00000000 1.00000000 1.00000000"/>
            </geometry>
            <material name="">
                <color rgba="0.8392157 0.8352941 0.7921569 1"/>
            </material>
        </visual>
    </link>
    <joint name="base_joint" type="fixed">
        <parent link="base"/>
        <child link="base_link"/>
        <origin rpy="0.00000000 0.00000000 0.00000000" xyz="0.00000000 0.00000000 0.00000000"/>
        <axis xyz="100"/>
    </joint>
    <joint name="joint1" type="revolute">
        <parent link="base_link"/>
        <child link="link_1"/>
        <origin rpy="0.00000000 0.00000000 0.00000000" xyz="0.00000000 0.00000000 0.00000000"/>
        <axis xyz="0.00000000 0.00000000 1.00000000"/>
        <limit lower="-3.14159265" upper="3.14159265" effort="0" velocity="0"/>
    </joint>
    <joint name="joint2" type="revolute">
        <parent link="link_1"/>
        <child link="link_2"/>
        <origin rpy="-1.57079633  0.00000000  0.00000000" xyz="0.15000000 0.00000000 0.40000000"/>
        <axis xyz="0.00000000 0.00000000 1.00000000"/>
        <limit lower="-3.14159265" upper="3.14159265" effort="0" velocity="0"/>
    </joint>
    <joint name="joint3" type="revolute">
        <parent link="link_2"/>
        <child link="link_3"/>
        <origin rpy="0.00000000  0.00000000 -1.57079633" xyz="0.00000000 -0.70700000  0.00000000"/>
        <axis xyz="0.00000000 0.00000000 1.00000000"/>
        <limit lower="-3.14159265" upper="3.14159265" effort="0" velocity="0"/>
    </joint>
    <joint name="joint4" type="revolute">
        <parent link="link_3"/>
        <child link="link_4"/>
        <origin rpy="-1.57079633  0.00000000  0.00000000" xyz="0.11000000 0.00000000 0.00000000"/>
        <axis xyz="0.00000000 0.00000000 1.00000000"/>
        <limit lower="-3.14159265" upper="3.14159265" effort="0" velocity="0"/>
    </joint>
    <joint name="joint5" type="revolute">
        <parent link="link_4"/>
        <child link="link_5"/>
        <origin rpy="1.57079633 0.00000000 0.00000000" xyz="0.00000000 0.00000000 0.63700000"/>
        <axis xyz="0.00000000 0.00000000 1.00000000"/>
        <limit lower="-3.14159265" upper="3.14159265" effort="0" velocity="0"/>
    </joint>
    <joint name="joint6" type="revolute">
        <parent link="link_5"/>
        <child link="link_6"/>
        <origin rpy="-1.57079633  0.00000000  0.00000000" xyz="0.08000000 0.00000000 0.00000000"/>
        <axis xyz="0.00000000 0.00000000 1.00000000"/>
        <limit lower="-3.14159265" upper="3.14159265" effort="0" velocity="0"/>
    </joint>
</robot>
